package app

import (
	"runtime/debug"

	"github.com/arquivei/foundationkit/errors"
	"github.com/arquivei/foundationkit/stringsutil"
	"github.com/rs/zerolog/log"
)

// Recover recovers from the panic and if panic persists, logs
// it with trace error. Should be called at the first line in
// the main function.
func Recover() {
	if r := recover(); r != nil {
		log.Fatal().
			Err(errors.NewFromRecover(r)).
			Str("panic_stack", stringsutil.Truncate(string(debug.Stack()), 1024)).
			Msg("[app] App terminated due to panic.")
	}
}
